Workbook

Sheet Graphiques
B1: ANALYSE FINANCIÈRE : ATR, GRAPHIQUES
B3: Graphiques Excel natifs : ils lisent l'onglet Indicateurs et se mettent à jour avec lui.

Sheet Indicateurs
B1: ANALYSE FINANCIÈRE : ATR, INDICATEURS CLÉS
B2: ATELIER TECHNIQUE DE REPARATIO, NCC 9908512B, activité : Entretien et réparations de machines. Toutes les valeurs sont des formules liées à l'onglet « États financiers ». Colonne 2026 : situation au 31/08/2026 (8 mois).
B4: Indicateur | C4: 2023 | D4: 2024 | E4: 2025 | F4: 2026 (8 mois) | G4: Formule
B5: ACTIVITÉ ET SOLDES DE GESTION (M FCFA)
B6: Chiffre d'affaires | C6: ='États financiers'!D73/1000000 -> 9640.0486 | D6: ='États financiers'!E73/1000000 -> 10753.141 | E6: ='États financiers'!F73/1000000 -> 11267.004 | F6: ='États financiers'!G73/1000000 -> 7113.0075 | G6: XB
B7: Marge commerciale | C7: ='États financiers'!D69/1000000 -> 127.31818 | D7: ='États financiers'!E69/1000000 -> 90.363165 | E7: ='États financiers'!F69/1000000 -> 53.658578 | F7: ='États financiers'!G69/1000000 -> 9.906332 | G7: XA = ventes de marchandises − coût d'achat des marchandises vendues
B8: Valeur ajoutée | C8: ='États financiers'!D87/1000000 -> 5138.9266 | D8: ='États financiers'!E87/1000000 -> 5774.071 | E8: ='États financiers'!F87/1000000 -> 6560.2538 | F8: ='États financiers'!G87/1000000 -> 3822.7062 | G8: XC
B9: Excédent brut d'exploitation (EBE) | C9: ='États financiers'!D89/1000000 -> 2727.2711 | D9: ='États financiers'!E89/1000000 -> 3115.0841 | E9: ='États financiers'!F89/1000000 -> 3804.8082 | F9: ='États financiers'!G89/1000000 -> 1949.5871 | G9: XD = VA − charges de personnel
B10: EBE hors plus-values de cessions courantes | C10: =('États financiers'!D89-'États financiers'!D145+'États financiers'!D146)/1000000 -> 2278.4261 | D10: =('États financiers'!E89-'États financiers'!E145+'États financiers'!E146)/1000000 -> 2926.7369 | E10: =('États financiers'!F89-'États financiers'!F145+'États financiers'!F146)/1000000 -> 3498.1776 | F10: =IF(COUNT('États financiers'!G145:G146)<2,"n.d.",('États financiers'!G89-'États financiers'!G145+'États financiers'!G146)/1000000) -> n.d. | G10: XD − produits (754) + VNC (654) des cessions courantes d'immobilisations ; 2026 : n.d. (754 et 654 non communiqués)
B11: Résultat d'exploitation | C11: ='États financiers'!D92/1000000 -> 229.38229 | D11: ='États financiers'!E92/1000000 -> 475.04488 | E11: ='États financiers'!F92/1000000 -> 1345.6269 | F11: ='États financiers'!G92/1000000 -> 447.50217 | G11: XE
B12: Résultat financier | C12: ='États financiers'!D98/1000000 -> -241.60021 | D12: ='États financiers'!E98/1000000 -> -206.71935 | E12: ='États financiers'!F98/1000000 -> -154.95397 | F12: ='États financiers'!G98/1000000 -> -141.61131 | G12: XF
B13: Résultat hors activités ordinaires | C13: ='États financiers'!D104/1000000 -> 0 | D13: ='États financiers'!E104/1000000 -> -0.377376 | E13: ='États financiers'!F104/1000000 -> -26.592432 | F13: ='États financiers'!G104/1000000 -> 5.834982 | G13: XH
B14: Résultat net | C14: ='États financiers'!D107/1000000 -> -36.883132 | D14: ='États financiers'!E107/1000000 -> 194.53441 | E14: ='États financiers'!F107/1000000 -> 924.98632 | F14: ='États financiers'!G107/1000000 -> 220.09994 | G14: XI
B15: Capacité d'autofinancement globale (CAFG) | C15: ='États financiers'!D111/1000000 -> 2012.1603 | D15: ='États financiers'!E111/1000000 -> 2643.9871 | E15: ='États financiers'!F111/1000000 -> 3051.4819 | F15: ='États financiers'!G111/1000000 -> 1716.3499 | G15: FA (TFT) ; 2026 : TFT reconstitué, 8 mois
B16: CROISSANCE
B17: Croissance, chiffre d'affaires | D17: =IFERROR(('États financiers'!E73-'États financiers'!D73)/ABS('États financiers'!D73),"") -> 0.11546547 | E17: =IFERROR(('États financiers'!F73-'États financiers'!E73)/ABS('États financiers'!E73),"") -> 0.04778721 | F17: =IFERROR(('États financiers'!G73*12/'États financiers'!G$3-'États financiers'!F73)/ABS('États financiers'!F73),"") -> -0.053030307 | G17: Variation sur un an ; 2026 : flux de 8 mois annualisés (× 12/8)
B18: Croissance, valeur ajoutée | D18: =IFERROR(('États financiers'!E87-'États financiers'!D87)/ABS('États financiers'!D87),"") -> 0.12359476 | E18: =IFERROR(('États financiers'!F87-'États financiers'!E87)/ABS('États financiers'!E87),"") -> 0.13615746 | F18: =IFERROR(('États financiers'!G87*12/'États financiers'!G$3-'États financiers'!F87)/ABS('États financiers'!F87),"") -> -0.12593942 | G18: Variation sur un an ; 2026 : flux de 8 mois annualisés (× 12/8)
B19: Croissance, EBE | D19: =IFERROR(('États financiers'!E89-'États financiers'!D89)/ABS('États financiers'!D89),"") -> 0.14219816 | E19: =IFERROR(('États financiers'!F89-'États financiers'!E89)/ABS('États financiers'!E89),"") -> 0.22141428 | F19: =IFERROR(('États financiers'!G89*12/'États financiers'!G$3-'États financiers'!F89)/ABS('États financiers'!F89),"") -> -0.23139865 | G19: Variation sur un an ; 2026 : flux de 8 mois annualisés (× 12/8)
B20: Croissance, EBE hors cessions courantes | D20: =IFERROR((D10-C10)/ABS(C10),"") -> 0.28454325 | E20: =IFERROR((E10-D10)/ABS(D10),"") -> 0.1952484 | F20: =IFERROR((F10*12/'États financiers'!G$3-E10)/ABS(E10),"n.d.") -> n.d. | G20: Variation sur un an ; 2026 : n.d.
B21: Croissance, résultat net | D21: =IFERROR(('États financiers'!E107-'États financiers'!D107)/ABS('États financiers'!D107),"") -> 6.2743462 | E21: =IFERROR(('États financiers'!F107-'États financiers'!E107)/ABS('États financiers'!E107),"") -> 3.7548726 | F21: =IFERROR(('États financiers'!G107*12/'États financiers'!G$3-'États financiers'!F107)/ABS('États financiers'!F107),"") -> -0.64307591 | G21: Variation sur un an (dénominateur en valeur absolue) ; 2026 : flux de 8 mois annualisés (× 12/8)
B22: Croissance, total du bilan | D22: =IFERROR(('États financiers'!E33-'États financiers'!D33)/ABS('États financiers'!D33),"") -> -0.12769968 | E22: =IFERROR(('États financiers'!F33-'États financiers'!E33)/ABS('États financiers'!E33),"") -> 0.10341357 | F22: =IFERROR(('États financiers'!G33-'États financiers'!F33)/ABS('États financiers'!F33),"") -> 0.030712997 | G22: Variation sur un an ; 2026 : 31/08/2026 vs 31/12/2025
B23: Croissance, capitaux propres | D23: =IFERROR(('États financiers'!E46-'États financiers'!D46)/ABS('États financiers'!D46),"") -> 0.033717589 | E23: =IFERROR(('États financiers'!F46-'États financiers'!E46)/ABS('États financiers'!E46),"") -> 0.076246133 | F23: =IFERROR(('États financiers'!G46-'États financiers'!F46)/ABS('États financiers'!F46),"") -> -0.045631636 | G23: Variation sur un an ; 2026 : 31/08/2026 vs 31/12/2025
B24: RENTABILITÉ
B25: Taux de valeur ajoutée | C25: =IFERROR('États financiers'!D87/'États financiers'!D73,"") -> 0.53308098 | D25: =IFERROR('États financiers'!E87/'États financiers'!E73,"") -> 0.53696597 | E25: =IFERROR('États financiers'!F87/'États financiers'!F73,"") -> 0.58225362 | F25: =IFERROR('États financiers'!G87/'États financiers'!G73,"") -> 0.53742474 | G25: VA / CA
B26: Marge d'EBE | C26: =IFERROR('États financiers'!D89/'États financiers'!D73,"") -> 0.28291052 | D26: =IFERROR('États financiers'!E89/'États financiers'!E73,"") -> 0.28969061 | E26: =IFERROR('États financiers'!F89/'États financiers'!F73,"") -> 0.33769476 | F26: =IFERROR('États financiers'!G89/'États financiers'!G73,"") -> 0.2740876 | G26: EBE / CA
B27: Marge d'EBE hors cessions courantes | C27: =IFERROR(('États financiers'!D89-'États financiers'!D145+'États financiers'!D146)/'États financiers'!D73,"") -> 0.23635007 | D27: =IFERROR(('États financiers'!E89-'États financiers'!E145+'États financiers'!E146)/'États financiers'!E73,"") -> 0.27217506 | E27: =IFERROR(('États financiers'!F89-'États financiers'!F145+'États financiers'!F146)/'États financiers'!F73,"") -> 0.31047984 | F27: =IF(COUNT('États financiers'!G145:G146)<2,"n.d.",IFERROR(('États financiers'!G89-'États financiers'!G145+'États financiers'!G146)/'États financiers'!G73,"")) -> n.d. | G27: EBE hors plus-values de cessions courantes / CA ; 2026 : n.d.
B28: Marge d'exploitation | C28: =IFERROR('États financiers'!D92/'États financiers'!D73,"") -> 0.023794723 | D28: =IFERROR('États financiers'!E92/'États financiers'!E73,"") -> 0.044177312 | E28: =IFERROR('États financiers'!F92/'États financiers'!F73,"") -> 0.11943076 | F28: =IFERROR('États financiers'!G92/'États financiers'!G73,"") -> 0.062913216 | G28: Résultat d'exploitation / CA
B29: Marge nette | C29: =IFERROR('États financiers'!D107/'États financiers'!D73,"") -> -0.0038260318 | D29: =IFERROR('États financiers'!E107/'États financiers'!E73,"") -> 0.018090938 | E29: =IFERROR('États financiers'!F107/'États financiers'!F73,"") -> 0.08209692 | F29: =IFERROR('États financiers'!G107/'États financiers'!G73,"") -> 0.030943302 | G29: Résultat net / CA
B30: Charges de personnel / valeur ajoutée | C30: =IFERROR(-'États financiers'!D88/'États financiers'!D87,"") -> 0.46929167 | D30: =IFERROR(-'États financiers'!E88/'États financiers'!E87,"") -> 0.46050471 | E30: =IFERROR(-'États financiers'!F88/'États financiers'!F87,"") -> 0.42002119 | F30: =IFERROR(-'États financiers'!G88/'États financiers'!G87,"") -> 0.48999818 | G30: −RK / XC
B31: Valeur ajoutée par salarié (M FCFA) | C31: =IFERROR('États financiers'!D87/'États financiers'!D147/1000000,"") -> 7.8697191 | D31: =IFERROR('États financiers'!E87/'États financiers'!E147/1000000,"") -> 8.1670028 | E31: =IFERROR('États financiers'!F87/'États financiers'!F147/1000000,"") | F31: =IFERROR('États financiers'!G87/'États financiers'!G147/1000000,"") | G31: VA / effectif salarié (note 27B)
B32: Charges de personnel par salarié (M FCFA) | C32: =IFERROR(-'États financiers'!D88/'États financiers'!D147/1000000,"") -> 3.6931936 | D32: =IFERROR(-'États financiers'!E88/'États financiers'!E147/1000000,"") -> 3.7609433 | E32: =IFERROR(-'États financiers'!F88/'États financiers'!F147/1000000,"") | F32: =IFERROR(-'États financiers'!G88/'États financiers'!G147/1000000,"") | G32: −RK / effectif salarié (note 27B)
B33: Rentabilité des capitaux propres (ROE) | C33: =IFERROR('États financiers'!D107/'États financiers'!D46,"") -> -0.0063927523 | D33: =IFERROR('États financiers'!E107/'États financiers'!E46,"") -> 0.032617795 | E33: =IFERROR('États financiers'!F107/'États financiers'!F46,"") -> 0.14410594 | F33: =IFERROR('États financiers'!G107*12/'États financiers'!G$3/'États financiers'!G46,"") -> 0.053894161 | G33: Résultat net / capitaux propres de clôture (CP) ; 2026 : résultat annualisé (× 12/8)
B34: Rentabilité de l'actif (ROA) | C34: =IFERROR('États financiers'!D107/'États financiers'!D33,"") -> -0.0032052869 | D34: =IFERROR('États financiers'!E107/'États financiers'!E33,"") -> 0.019380702 | E34: =IFERROR('États financiers'!F107/'États financiers'!F33,"") -> 0.083516075 | F34: =IFERROR('États financiers'!G107*12/'États financiers'!G$3/'États financiers'!G33,"") -> 0.028920659 | G34: Résultat net / total du bilan ; 2026 : résultat annualisé (× 12/8)
B35: STRUCTURE FINANCIÈRE ET ENDETTEMENT
B36: Capitaux propres (M FCFA) | C36: ='États financiers'!D46/1000000 -> 5769.5231 | D36: ='États financiers'!E46/1000000 -> 5964.0575 | E36: ='États financiers'!F46/1000000 -> 6418.7938 | F36: ='États financiers'!G46/1000000 -> 6125.8938 | G36: CP
B37: Autonomie financière | C37: =IFERROR('États financiers'!D46/'États financiers'!D33,"") -> 0.50139389 | D37: =IFERROR('États financiers'!E46/'États financiers'!E33,"") -> 0.59417573 | E37: =IFERROR('États financiers'!F46/'États financiers'!F33,"") -> 0.57954637 | F37: =IFERROR('États financiers'!G46/'États financiers'!G33,"") -> 0.53661953 | G37: Capitaux propres / total du bilan
B38: Dettes financières (M FCFA) | C38: =('États financiers'!D47+'États financiers'!D48)/1000000 -> 3666.5276 | D38: =('États financiers'!E47+'États financiers'!E48)/1000000 -> 2042.6765 | E38: =('États financiers'!F47+'États financiers'!F48)/1000000 -> 2807.0756 | F38: =('États financiers'!G47+'États financiers'!G48)/1000000 -> 3327.8299 | G38: DA + DB (emprunts et location-acquisition)
B39: Endettement net (M FCFA) | C39: =(('États financiers'!D47+'États financiers'!D48+'États financiers'!D61)-'États financiers'!D31)/1000000 -> 3037.0752 | D39: =(('États financiers'!E47+'États financiers'!E48+'États financiers'!E61)-'États financiers'!E31)/1000000 -> 1134.1773 | E39: =(('États financiers'!F47+'États financiers'!F48+'États financiers'!F61)-'États financiers'!F31)/1000000 -> 1915.5771 | F39: =(('États financiers'!G47+'États financiers'!G48+'États financiers'!G61)-'États financiers'!G31)/1000000 -> 2991.2018 | G39: DA + DB + trésorerie-passif − trésorerie-actif
B40: Gearing | C40: =IFERROR((('États financiers'!D47+'États financiers'!D48+'États financiers'!D61)-'États financiers'!D31)/'États financiers'!D46,"") -> 0.52639969 | D40: =IFERROR((('États financiers'!E47+'États financiers'!E48+'États financiers'!E61)-'États financiers'!E31)/'États financiers'!E46,"") -> 0.19016873 | E40: =IFERROR((('États financiers'!F47+'États financiers'!F48+'États financiers'!F61)-'États financiers'!F31)/'États financiers'!F46,"") -> 0.29843256 | F40: =IFERROR((('États financiers'!G47+'États financiers'!G48+'États financiers'!G61)-'États financiers'!G31)/'États financiers'!G46,"") -> 0.48828823 | G40: Endettement net / capitaux propres
B41: Capacité de remboursement | C41: =IFERROR(('États financiers'!D47+'États financiers'!D48)/'États financiers'!D111,"") -> 1.8221847 | D41: =IFERROR(('États financiers'!E47+'États financiers'!E48)/'États financiers'!E111,"") -> 0.77257431 | E41: =IFERROR(('États financiers'!F47+'États financiers'!F48)/'États financiers'!F111,"") -> 0.91990572 | F41: =IFERROR(('États financiers'!G47+'États financiers'!G48)/('États financiers'!G111*12/'États financiers'!G$3),"") -> 1.2925996 | G41: Dettes financières / CAFG ; 2026 : CAFG annualisée (× 12/8)
...

Sheet États financiers
B1: ÉTATS FINANCIERS : ATR, SYSCOHADA RÉVISÉ (SYSTÈME NORMAL)
B2: ATELIER TECHNIQUE DE REPARATIO, NCC 9908512B. Montants en FCFA. Source : liasses DGI certifiées 2023, 2024 et 2025, colonne N de chaque liasse ; états financiers intermédiaires au 31/08/2026 (8 mois) pour la colonne 2026. Saisies en bleu, sous-totaux en formules. TFT 2026 reconstitué par formules (absent des EFI intermédiaires).
C3: Durée de la période (mois) | D3: 12 | E3: 12 | F3: 12 | G3: 8
B4: Code | C4: Bilan, actif (montants nets) | D4: 2023 | E4: 2024 | F4: 2025 | G4: 2026 (8 mois)
B5: AD | C5: Immobilisations incorporelles | D5: =D6+D7+D8+D9 -> 19467954 | E5: =E6+E7+E8+E9 -> 7025740 | F5: =F6+F7+F8+F9 -> 1110808 | G5: =G6+G7+G8+G9 -> 669030
B6: AE | C6: Frais de développement et de prospection | D6: 0 | E6: 0 | F6: 0 | G6: 0
B7: AF | C7: Brevets, licences, logiciels et droits similaires | D7: 19467954 | E7: 7025740 | F7: 1110808 | G7: 669030
B8: AG | C8: Fonds commercial et droit au bail | D8: 0 | E8: 0 | F8: 0 | G8: 0
B9: AH | C9: Autres immobilisations incorporelles | D9: 0 | E9: 0 | F9: 0 | G9: 0
B10: AI | C10: Immobilisations corporelles | D10: =D11+D12+D13+D14+D15 -> 6633533334 | E10: =E11+E12+E13+E14+E15 -> 5249498091 | F10: =F11+F12+F13+F14+F15 -> 6224455586 | G10: =G11+G12+G13+G14+G15 -> 6526748682
B11: AJ | C11: Terrains | D11: 0 | E11: 0 | F11: 0 | G11: 0
B12: AK | C12: Bâtiments | D12: 2046248 | E12: 1937155 | F12: 1828360 | G12: 1755929
B13: AL | C13: Aménagements, agencements et installations | D13: 80618206 | E13: 152817020 | F13: 171498799 | G13: 275115385
B14: AM | C14: Matériel, mobilier et actifs biologiques | D14: 65606455 | E14: 66307926 | F14: 155921190 | G14: 247474694
B15: AN | C15: Matériel de transport | D15: 6485262425 | E15: 5028435990 | F15: 5895207237 | G15: 6002402674
B16: AP | C16: Avances et acomptes versés sur immobilisations | D16: 2000000 | E16: 0 | F16: 0 | G16: 0
B17: AQ | C17: Immobilisations financières | D17: =D18+D19 -> 110979610 | E17: =E18+E19 -> 112459610 | F17: =F18+F19 -> 114539610 | G17: =G18+G19 -> 24593748
B18: AR | C18: Titres de participation | D18: 0 | E18: 0 | F18: 0 | G18: 0
B19: AS | C19: Autres immobilisations financières | D19: 110979610 | E19: 112459610 | F19: 114539610 | G19: 24593748
B20: AZ | C20: TOTAL ACTIF IMMOBILISÉ | D20: =D5+D10+D16+D17 -> 6765980898 | E20: =E5+E10+E16+E17 -> 5368983441 | F20: =F5+F10+F16+F17 -> 6340106004 | G20: =G5+G10+G16+G17 -> 6552011460
B21: BA | C21: Actif circulant HAO | D21: 0 | E21: 0 | F21: 0 | G21: 0
B22: BB | C22: Stocks et en-cours | D22: 598277176 | E22: 373634779 | F22: 263326659 | G22: 273578811
B23: BG | C23: Créances et emplois assimilés | D23: =D24+D25+D26 -> 3513256870 | E23: =E24+E25+E26 -> 3386413895 | F23: =F24+F25+F26 -> 3580617088 | G23: =G24+G25+G26 -> 4253493218
B24: BH | C24: Fournisseurs, avances versées | D24: 168485021 | E24: 92046554 | F24: 516517573 | G24: 870694255
B25: BI | C25: Clients | D25: 3264136795 | E25: 2987525511 | F25: 2779025678 | G25: 3084401318
B26: BJ | C26: Autres créances | D26: 80635054 | E26: 306841830 | F26: 285073837 | G26: 298397645
B27: BK | C27: TOTAL ACTIF CIRCULANT | D27: =D21+D22+D23 -> 4111534046 | E27: =E21+E22+E23 -> 3760048674 | F27: =F21+F22+F23 -> 3843943747 | G27: =G21+G22+G23 -> 4527072029
B28: BQ | C28: Titres de placement | D28: 0 | E28: 0 | F28: 0 | G28: 0
B29: BR | C29: Valeurs à encaisser | D29: 0 | E29: 0 | F29: 80907578 | G29: 0
B30: BS | C30: Banques, chèques postaux, caisse et assimilés | D30: 629452469 | E30: 908499225 | F30: 810590990 | G30: 336628114
B31: BT | C31: TOTAL TRÉSORERIE-ACTIF | D31: =D28+D29+D30 -> 629452469 | E31: =E28+E29+E30 -> 908499225 | F31: =F28+F29+F30 -> 891498568 | G31: =G28+G29+G30 -> 336628114
B32: BU | C32: Écart de conversion-actif | D32: 0 | E32: 0 | F32: 0 | G32: 0
B33: BZ | C33: TOTAL ACTIF | D33: =D20+D27+D31+D32 -> 11506967413 | E33: =E20+E27+E31+E32 -> 10037531340 | F33: =F20+F27+F31+F32 -> 11075548319 | G33: =G20+G27+G31+G32 -> 11415711603
B35: Code | C35: Bilan, passif | D35: 2023 | E35: 2024 | F35: 2025 | G35: 2026 (8 mois)
B36: CA | C36: Capital | D36: 1710000000 | E36: 1710000000 | F36: 1710000000 | G36: 1710000000
B37: CB | C37: Apporteurs, capital non appelé (−) | D37: 0 | E37: 0 | F37: 0 | G37: 0
B38: CD | C38: Primes liées au capital social | D38: 0 | E38: 0 | F38: 0 | G38: 0
B39: CE | C39: Écarts de réévaluation | D39: 0 | E39: 0 | F39: 0 | G39: 0
B40: CF | C40: Réserves indisponibles | D40: 91633230 | E40: 91633230 | F40: 111086671 | G40: 203585303
B41: CG | C41: Réserves libres | D41: 3800000000 | E41: 3800000000 | F41: 3671750000 | G41: 3800000000
...

Sheet Points d'attention
B1: POINTS D'ATTENTION
B2: Contrôles automatiques : écart nul attendu. Les totaux publiés sont saisis tels qu'ils figurent dans chaque liasse. La colonne 2026 reprend les EFI intermédiaires au 31/08/2026.
B4: Totaux publiés dans les liasses (FCFA) | C4: 2023 | D4: 2024 | E4: 2025 | F4: 2026 (8 mois)
B5: Total actif publié (BZ) | C5: 11506967413 | D5: 10037531340 | E5: 11075548319 | F5: 11415711603
B6: Total passif publié (DZ) | C6: 11506967413 | D6: 10037531340 | E6: 11075548319 | F6: 11415711603
B7: Capitaux propres publiés (CP) | C7: 5769523109 | D7: 5964057516 | E7: 6418793836 | F7: 6125893771
B8: Résultat net publié (XI) | C8: -36883132 | D8: 194534407 | E8: 924986320 | F8: 220099936
B9: Flux opérationnels publiés (ZB) | C9: 1543140101 | D9: 2944178904 | E9: 2756303021 | F9: n.a.
B10: Trésorerie nette publiée au 31/12 (ZH) | C10: 629452469 | D10: 908499225 | E10: 891498568 | F10: n.a.
B12: Contrôle de cohérence (écart en FCFA) | C12: 2023 | D12: 2024 | E12: 2025 | F12: 2026 (8 mois)
B13: Total actif recalculé − total actif publié | C13: ='États financiers'!D33-C5 -> 0 | D13: ='États financiers'!E33-D5 -> 0 | E13: ='États financiers'!F33-E5 -> 0 | F13: ='États financiers'!G33-F5 -> 0
B14: Total passif recalculé − total passif publié | C14: ='États financiers'!D63-C6 -> 0 | D14: ='États financiers'!E63-D6 -> 0 | E14: ='États financiers'!F63-E6 -> 0 | F14: ='États financiers'!G63-F6 -> 0
B15: Total actif − total passif (recalculés) | C15: ='États financiers'!D33-'États financiers'!D63 -> 0 | D15: ='États financiers'!E33-'États financiers'!E63 -> 0 | E15: ='États financiers'!F33-'États financiers'!F63 -> 0 | F15: ='États financiers'!G33-'États financiers'!G63 -> 0
B16: Capitaux propres recalculés − publiés | C16: ='États financiers'!D46-C7 -> 0 | D16: ='États financiers'!E46-D7 -> 0 | E16: ='États financiers'!F46-E7 -> 0 | F16: ='États financiers'!G46-F7 -> 0
B17: Résultat net recalculé − publié | C17: ='États financiers'!D107-C8 -> 0 | D17: ='États financiers'!E107-D8 -> 0 | E17: ='États financiers'!F107-E8 -> 0 | F17: ='États financiers'!G107-F8 -> 0
B18: Résultat au bilan (CJ) − résultat du compte de résultat (XI) | C18: ='États financiers'!D43-'États financiers'!D107 -> 0 | D18: ='États financiers'!E43-'États financiers'!E107 -> 0 | E18: ='États financiers'!F43-'États financiers'!F107 -> 0 | F18: ='États financiers'!G43-'États financiers'!G107 -> 0
B19: Flux opérationnels recalculés − publiés | C19: ='États financiers'!D116-C9 -> 0 | D19: ='États financiers'!E116-D9 -> 0 | E19: ='États financiers'!F116-E9 -> 0 | F19: n.a.
B20: Trésorerie TFT (ZH) − trésorerie bilan (BT − DT) | C20: ='États financiers'!D134-('États financiers'!D31-'États financiers'!D61) -> 0 | D20: ='États financiers'!E134-('États financiers'!E31-'États financiers'!E61) -> 0 | E20: ='États financiers'!F134-('États financiers'!F31-'États financiers'!F61) -> 0 | F20: ='États financiers'!G134-('États financiers'!G31-'États financiers'!G61) -> 0
B21: Trésorerie au 1er janvier (ZA) − trésorerie nette N-1 au bilan | D21: ='États financiers'!E110-('États financiers'!D31-'États financiers'!D61) -> 0 | E21: ='États financiers'!F110-('États financiers'!E31-'États financiers'!E61) -> 0 | F21: ='États financiers'!G110-('États financiers'!F31-'États financiers'!F61) -> 0
B23: ANOMALIES RELEVÉES DANS LES LIASSES ET TRAITEMENT RETENU
B24: Liasse 2023 : le bilan intervertit les stocks (BB, publiés à 110 979 610 FCFA) et les autres immobilisations financières (AS, publiées à 598 277 176 FCFA). Les notes 4 et 6 de la même liasse et la colonne N-1 de la liasse 2024 donnent l'inverse. Le classeur retient les montants corrigés : stocks 598 277 176 FCFA, immobilisations financières 110 979 610 FCFA. Le total du bilan ne change pas. L'actif immobilisé passe de 7 253 M à 6 766 M FCFA et l'actif circulant de 3 624 M à 4 112 M FCFA.
B25: Liasse 2025, colonne N-1 : les fournisseurs d'exploitation 2024 figurent pour 1 037 228 804 FCFA contre 1 037 238 804 FCFA dans la liasse 2024. Le passif N-1 de la liasse 2025 ne s'équilibre donc pas avec l'actif (écart de 10 000 FCFA). Le classeur retient la liasse 2024.
B26: Liasse 2024, tableau de calcul de la CAF : les produits de cessions courantes (compte 754) sont ajoutés au lieu d'être déduits. La CAF d'exploitation publiée (3 514 M FCFA) ressort à 2 927 M FCFA après correction du signe. Les liasses 2023 et 2025 appliquent le bon signe.
B27: Liasse 2025, note 21 : les autres produits s'élèvent à 2 404 M FCFA contre 3 175 M FCFA en ligne TH du compte de résultat. L'écart de 770 591 564 FCFA égale exactement les dépréciations de l'actif circulant au 31/12/2024. Il s'agit vraisemblablement de leur reprise, à confirmer avec la société. La note 26 totalise 2 652 823 095 FCFA contre 2 652 823 081 FCFA en ligne RJ (écart de 14 FCFA).
B28: Note 27B non renseignée dans la liasse 2025 : l'effectif 2025 et les ratios par salarié restent vides.
B29: Les produits de cessions courantes (754) ne figurent qu'en milliers de FCFA, dans le tableau de calcul de la CAF. L'EBE hors cessions courantes porte donc une imprécision inférieure à 1 000 FCFA. En 2025, il égale la CAF d'exploitation publiée (3 498 M FCFA).
B31: POINTS D'ATTENTION ANALYTIQUES
B32: L'activité progresse avec régularité. Le chiffre d'affaires passe de 9 640 M FCFA en 2023 à 11 267 M FCFA en 2025 (+11,5 % puis +4,8 %). Les travaux et services représentent 98,6 % du chiffre d'affaires 2025.
B33: L'EBE publié inclut le résultat des cessions courantes de véhicules : 449 M FCFA en 2023, 188 M FCFA en 2024 et 307 M FCFA en 2025. Hors cet effet, l'EBE passe de 2 278 M à 3 498 M FCFA et la marge de 23,6 % à 31,0 % du chiffre d'affaires.
B34: L'EBE 2025 intègre aussi un effet net de +126 M FCFA sur les dépréciations à court terme : 771 M FCFA de reprise probable (voir anomalies) et 645 M FCFA de nouvelles dotations en autres charges.
B35: Le résultat net se redresse : −37 M FCFA en 2023, 195 M FCFA en 2024 et 925 M FCFA en 2025. Le ROE atteint 14,4 % en 2025. Les dotations aux amortissements et provisions (2 459 M FCFA) absorbent 65 % de l'EBE. Elles reflètent une flotte de matériel de transport de 18 982 M FCFA en valeur brute.
... B54: Informations à obtenir de la société : détail des comptes 754 et 654 et des autres produits (TH), tableau des immobilisations (acquisitions, nouveaux contrats de location-acquisition, cessions), date de paiement des dividendes, effectif au 31/08/2026.
