Workbook

Sheet PT_Actuariat
A1: PLAN DE TRAVAIL : AUDIT DU FPPN, 2020 AU 31 AOÛT 2026, VOLET ACTUARIEL ET STATISTIQUE
A2: Pointage au 23/10/2026. Taux de réalisation pondérés par le temps estimé du scénario choisi ci-contre (cellule orange). | E2: Scénario de pondération | F2: Données dégradées | K2: Taux de la mission | L2: =L56
A4: N° | B4: Description des activités | C4: Fait par | D4: Interlocuteurs FPPN | E4: Livrables | F4: Observations et pièces justificatives (pointage au 23/10/2026) | G4: Temps estimé, données correctes (j) | H4: Temps estimé, données dégradées (j) | I4: Début prévu | J4: Fin prévue | K4: Statut | L4: Taux de réalisation | M4: Temps réalisé équivalent (j)
A7: 1 | B7: Phase 1 : Cadrage : textes, garanties, règles de calcul | F7: Estimation : Lire les statuts et les règles de chaque prestation, puis fixer les hypothèses. | G7: =SUM(G8:G12) | H7: =SUM(H8:H12) | I7: =MIN(I8:I12) | J7: =MAX(J8:J12) | K7: =IF(L7>=1,"Effectuée",IF(AND(L7=0,COUNTIF(K8:K12,"Bloquée")>0),"Bloquée",IF(L7=0,"Non réalisée","En cours"))) | L7: =IFERROR(M7/IF($F$2="Données correctes",G7,H7),0) | M7: =SUM(M8:M12)
A8: 1.1 | B8: Réunion de lancement : présentation de l'équipe et de la démarche, périmètre (01/01/2020 au 31/08/2026) et quatre questions de la mission | C8: Actuaire Adenka | D8: Direction générale, DAF | E8: - Comptes rendus de la réunion de lancement - PBC actuarielle pointée - Guides, comptes rendus et notes d'entretiens - Hypothèses retenues (tables, taux, inflation) | F8: Comptes rendus des 13 et 14/10/2026 (FPPN_CR_reunion_de_lancement_Adenka_20261013.pptx, FPPN_Compte_rendu_reunion_de_lancement_20261014.pptx). | G8: 0.25 | H8: 0.25 | I8: 46308 | J8: 46309 | K8: Effectuée | L8: 1 | M8: =IF($F$2="Données correctes",G8,H8)*L8
A9: 1.2 | B9: Élaborer la liste des documents et données (PBC actuarielle), la compléter après chaque entretien et pointer les envois reçus (15/10/2026, lots 1 à 3) | C9: Actuaire Adenka | D9: Chef comptable, responsable des cotisations | F9: PBC pointée au 23/10/2026 (FPPN_PBC_complete_pointee_20261023.xlsx) : 90 items après fusion des doublons, dont 6 reçus, 39 partiellement reçus et 45 non reçus. Questions et documents à transmettre (FPPN_Demandes_au_FPPN_20261023.xlsx : 26 questions, 84 documents). Reste : relances. | G9: 0.5 | H9: 0.75 | I9: 46309 | J9: 46325 | K9: En cours | L9: 0.8 | M9: =IF($F$2="Données correctes",G9,H9)*L9
A10: 1.3 | B10: Lire les statuts, le règlement intérieur, le cahier du régime des prestations sociales et les règles de chaque produit (maladie, décès, EFC, PEP, Grenier, flotte automobile, MEDOC) | C10: Actuaire Adenka | D10: Chef de service Assurance, sinistres et prestations | F10: Rapport du 23/10/2026, diapositives 24 à 27 (cadre juridique, statuts et règlement intérieur, garanties et produits). Versions des statuts antérieures à 2023 non reçues. Item PBC attendu : 1. | G10: 0.5 | H10: 0.75 | I10: 46310 | J10: 46315 | K10: En cours | L10: 0.9 | M10: =IF($F$2="Données correctes",G10,H10)*L10
A11: 1.4 | B11: Préparer les guides d'entretien et conduire les entretiens : sinistres et prestations (16/10/2026) ; cotisations, placements et provisions (19/10/2026) | C11: Actuaire Adenka | D11: Chef de service Assurance, sinistres et prestations ; responsable des cotisations ; chef comptable | F11: Guides (FPPN_Guides_entretiens_actuariat_20261016.xlsx et _20261019.xlsx) ; quatre comptes rendus et notes internes (dossier entretiens) ; demandes complémentaires ajoutées à la PBC. | G11: 0.5 | H11: 0.75 | I11: 46310 | J11: 46315 | K11: Effectuée | L11: 1 | M11: =IF($F$2="Données correctes",G11,H11)*L11
A12: 1.5 | B12: Fixer les hypothèses : tables de mortalité CIMA, taux d'actualisation (rendements de l'État de Côte d'Ivoire), inflation médicale (IHPC santé), âge de départ à la retraite, règles de calcul par garantie | C12: Actuaire Adenka | D12: Chef comptable | F12: Tables retenues (rapport du 23/10/2026, diapositives 205 à 211). SMIG de 75 000 FCFA (décret n° 2022-986 du 21/12/2022) appliqué au plafond de l'indemnité de départ (diapositive 133). Rendements lus dans les grands livres (diapositive 153). Reste : âge de départ du personnel et hypothèses de projection (phase 7). Items PBC attendus : 13, 78. | G12: 0.25 | H12: 0.5 | I12: 46314 | J12: 46318 | K12: En cours | L12: 0.7 | M12: =IF($F$2="Données correctes",G12,H12)*L12
A13: 2 | B13: Phase 2 : Contrôle et rapprochement des données | F13: Estimation : Les fichiers doivent coller avec la comptabilité. Le cas dégradé suppose des relances, des fichiers incomplets et des écarts à expliquer. | G13: =SUM(G14:G20) | H13: =SUM(H14:H20) | I13: =MIN(I14:I20) | J13: =MAX(J14:J20) | K13: =IF(L13>=1,"Effectuée",IF(AND(L13=0,COUNTIF(K14:K20,"Bloquée")>0),"Bloquée",IF(L13=0,"Non réalisée","En cours"))) | L13: =IFERROR(M13/IF($F$2="Données correctes",G13,H13),0) | M13: =SUM(M14:M20)
A14: 2.1 | B14: Extraire et inventorier les fichiers reçus (envoi du 15/10/2026 et nouveaux fichiers du 22/10/2026) | C14: Actuaire Adenka | D14: Responsable des cotisations et informatique | E14: - Inventaire des fichiers reçus - Partie 3 du rapport (données et qualité) - Note sur les anomalies de données - Onglets 1_ du classeur des calculs | F14: Extraction FPPN_extraction_20261018_1939.zip : 4 287 fichiers, journal journal_fichiers.csv. Envois du 22/10/2026 inventoriés. Fichiers vides ou endommagés recensés (rapport du 23/10/2026, diapositive 44). | G14: 0.5 | H14: 0.75 | I14: 46310 | J14: 46317 | K14: Effectuée | L14: 1 | M14: =IF($F$2="Données correctes",G14,H14)*L14
A15: 2.2 | B15: Contrôles de qualité : vrai format des fichiers, lignes de total, montants doublés, doublons, fichiers vides ou endommagés | C15: Actuaire Adenka | F15: Rapport du 23/10/2026, diapositives 37 à 45 (contrôles, qualité des bases variable par variable). Vérification indépendante des chiffres (FPPN_Verification_coherence_20261023.xlsx) : 506 feuilles de précomptes, 43 102 485 135 FCFA, 7 balances identiques. | G15: 0.75 | H15: 1.25 | I15: 46311 | J15: 46315 | K15: Effectuée | L15: 1 | M15: =IF($F$2="Données correctes",G15,H15)*L15
A16: 2.3 | B16: Rapprocher les fichiers aller et retour des précomptes (Solde, CGRAE, GNA) par poste et par mois | C16: Actuaire Adenka | D16: Responsable des cotisations | F16: Rapport du 23/10/2026, diapositives 42 et 43 (rapprochement aller et retour, écarts du PEP) ; classeur FPPN_Calculs_rapport_20261023.xlsx, onglet 1_aller_retour. | G16: 0.5 | H16: 1 | I16: 46311 | J16: 46315 | K16: Effectuée | L16: 1 | M16: =IF($F$2="Données correctes",G16,H16)*L16
A17: 2.4 | B17: Mesurer la couverture de la période (2020 au 31/08/2026) par poste et par sens, et obtenir les précomptes manquants | C17: Actuaire Adenka | D17: Responsable des cotisations | F17: Couverture mesurée de janvier 2020 à août 2026 (rapport du 23/10/2026, diapositive 39). Restent vides : fichiers maladie 936 et décès 8Z6 de décembre 2024. Fichier retour 9X4 de décembre 2024 manquant (diapositive 44). Items PBC attendus : 38, 39, 40. | G17: 0.5 | H17: 1.5 | I17: 46311 | J17: 46332 | K17: En cours | L17: 0.8 | M17: =IF($F$2="Données correctes",G17,H17)*L17
A18: 2.5 | B18: Rapprocher les cotisations, les prestations et l'épargne des fichiers avec la comptabilité (balances Sage 100) | C18: Actuaire Adenka | D18: Chef comptable | F18: Cotisations comptabilisées et précomptées rapprochées (rapport du 23/10/2026, diapositive 59). Contrôles croisés états financiers, effectifs et rapprochements bancaires (diapositives 47 à 49). Reste : comptes individuels d'épargne. Items PBC attendus : 9. | G18: 1 | H18: 1.5 | I18: 46314 | J18: 46339 | K18: En cours | L18: 0.6 | M18: =IF($F$2="Données correctes",G18,H18)*L18
A19: 2.6 | B19: Contrôler les bases de prestations maladie et décès (une ligne par dossier) et les rapprocher des montants comptabilisés | C19: Actuaire Adenka | D19: Chef de service Assurance, sinistres et prestations | F19: Aucune base de prestations extraite du logiciel. Le journal SIN et les états décès de fin d'année servent de base provisoire (rapport du 23/10/2026, diapositives 110 à 118). Items PBC attendus : 16, 47. | G19: 0.5 | H19: 1.5 | I19: 46321 | J19: 46339 | K19: Bloquée | L19: 0.25 | M19: =IF($F$2="Données correctes",G19,H19)*L19
A20: 2.7 | B20: Documenter les anomalies de données et les points à clarifier avec le FPPN | C20: Actuaire Adenka | D20: Chef comptable, responsable des cotisations | F20: Note sur les anomalies de données du 19/10/2026. Vérification de cohérence du 23/10/2026 (FPPN_Verification_coherence_20261023.xlsx, onglet 1_Anomalies). Questions au FPPN (rapport du 23/10/2026, diapositives 229 et 230). À tenir à jour à chaque envoi. | G20: 0.25 | H20: 0.5 | I20: 46314 | J20: 46339 | K20: En cours | L20: 0.8 | M20: =IF($F$2="Données correctes",G20,H20)*L20
A21: 3 | B21: Phase 3 : Évaluation des engagements | F21: Estimation : Un modèle par garantie, relancé à 8 dates (du 31/12/2019 au 31/08/2026). | G21: =SUM(G22:G27) | H21: =SUM(H22:H27) | I21: =MIN(I22:I27) | J21: =MAX(J22:J27) | K21: =IF(L21>=1,"Effectuée",IF(AND(L21=0,COUNTIF(K22:K27,"Bloquée")>0),"Bloquée",IF(L21=0,"Non réalisée","En cours"))) | L21: =IFERROR(M21/IF($F$2="Données correctes",G21,H21),0) | M21: =SUM(M22:M27)
A22: 3.1 | B22: Analyser les effectifs (cotisants, entrées et sorties, structure, ancienneté) et les cotisations (taux, valeur réelle, nouvelles recrues) | C22: Actuaire Adenka | D22: Responsable des cotisations | E22: - Parties 4 à 8 du rapport (effectifs, cotisations, sinistralité, épargne, Grenier, retraités) - Modèle d'évaluation par garantie - Engagements aux 8 dates d'arrêté | F22: Rapport du 23/10/2026, partie 4 (diapositives 50 à 62). Limite : dates de naissance absentes des fichiers de précomptes (diapositive 45), fichier des ayants droit non reçu. Items PBC attendus : 4, 43. | G22: 1 | H22: 1 | I22: 46311 | J22: 46316 | K22: Effectuée | L22: 1 | M22: =IF($F$2="Données correctes",G22,H22)*L22
A23: 3.2 | B23: Analyser la sinistralité et le résultat par garantie (prestations sur cotisations, nature des risques, croissance des prestations, frais de gestion) | C23: Actuaire Adenka | D23: Chef de service Assurance, sinistres et prestations | F23: Rapport du 23/10/2026, partie 5 (diapositives 63 à 77) et ratios par garantie (diapositive 182) ; classeur FPPN_Calculs_rapport_20261023.xlsx, onglets 3_, 12_sinistralite_variantes et 28_ratios_garantie. | G23: 1 | H23: 1 | I23: 46311 | J23: 46316 | K23: Effectuée | L23: 1 | M23: =IF($F$2="Données correctes",G23,H23)*L23
A24: 3.3 | B24: Analyser l'épargne (PEP, EFC), les prêts du Grenier, les retraités CGRAE et les produits annexes | C24: Actuaire Adenka | D24: Chef comptable | F24: Rapport du 23/10/2026, parties 6 à 8 (diapositives 78 à 104) ; classeur FPPN_Calculs_rapport_20261023.xlsx, onglets 4_, 5_ et 6_. | G24: 0.5 | H24: 0.5 | I24: 46311 | J24: 46316 | K24: Effectuée | L24: 1 | M24: =IF($F$2="Données correctes",G24,H24)*L24
A25: 3.4 | B25: Construire le modèle d'évaluation par garantie (décès et allocations, maladie, EFC, PEP) : formules, tables, taux, données individuelles | C25: Actuaire Adenka | F25: Méthodes retenues chiffrées sur les documents reçus : provision maladie, allocations décès, intérêts dus sur l'épargne, provision du personnel agent par agent (rapport du 23/10/2026, diapositives 89, 114, 118 et 122 à 133). Méthodes écartées en annexe (diapositives 232 à 239). | G25: 1.5 | H25: 2 | I25: 46318 | J25: 46331 | K25: En cours | L25: 0.5 | M25: =IF($F$2="Données correctes",G25,H25)*L25
A26: 3.5 | B26: Lancer le modèle aux 8 dates d'arrêté (31/12/2019 à 31/12/2025 et 31/08/2026) et expliquer l'évolution des engagements | C26: Actuaire Adenka | F26: Calculs par âge impossibles : dates de naissance absentes (rapport du 23/10/2026, diapositive 45). Analyses en attente et méthode retenue pour chacune (diapositive 228). Items PBC attendus : 4, 16, 43, 47. | G26: 1.5 | H26: 2.5 | I26: 46329 | J26: 46339 | K26: Bloquée | L26: 0.1 | M26: =IF($F$2="Données correctes",G26,H26)*L26
A27: 3.6 | B27: Conclure sur les engagements envers les adhérents et leurs ayants droit | C27: Actuaire Adenka | F27: Conclusion établie sur les documents reçus (rapport du 23/10/2026, diapositive 134). Les analyses en attente la préciseront sans en changer le sens (diapositive 228). | G27: 0.5 | H27: 1 | I27: 46316 | J27: 46339 | K27: En cours | L27: 0.6 | M27: =IF($F$2="Données correctes",G27,H27)*L27
A28: 4 | B28: Phase 4 : Revue des provisions | F28: Estimation : Comparer les provisions au bilan avec mon recalcul, et les provisions passées avec les paiements réels. | G28: =SUM(G29:G33) | H28: =SUM(H29:H33) | I28: =MIN(I29:I33) | J28: =MAX(J29:J33) | K28: =IF(L28>=1,"Effectuée",IF(AND(L28=0,COUNTIF(K29:K33,"Bloquée")>0),"Bloquée",IF(L28=0,"Non réalisée","En cours"))) | L28: =IFERROR(M28/IF($F$2="Données correctes",G28,H28),0) | M28: =SUM(M29:M33)
A29: 4.1 | B29: Inventorier les provisions et dépréciations au bilan par nature et par date, et choisir les formules de contrôle | C29: Actuaire Adenka | D29: Chef comptable | E29: - Revue des provisions (rapport, partie 9) - Recalcul des provisions et tableau de liquidation - Conclusion sur la suffisance des provisions | F29: Rapport du 23/10/2026, diapositives 105 à 109 ; classeur FPPN_Calculs_rapport_20261023.xlsx, onglets 12_provisions_inventaire, 12_psap_rapprochement et 8_provisions_mois. | G29: 0.5 | H29: 0.75 | I29: 46314 | J29: 46316 | K29: Effectuée | L29: 1 | M29: =IF($F$2="Données correctes",G29,H29)*L29
A30: 4.2 | B30: Recalculer la provision pour prestations à payer maladie (sinistres tardifs par Chain Ladder) et la provision pour allocations décès | C30: Actuaire Adenka | D30: Chef comptable ; chef de service Assurance, sinistres et prestations | F30: Provision maladie mesurée sur les factures arrivées après la clôture et provision décès sur les dossiers connus (rapport du 23/10/2026, diapositives 110 à 119). Reste : base des prestations datée et liste des dossiers non payés. Items PBC attendus : 7, 47, 48, 64. | G30: 1 | H30: 1.75 | I30: 46322 | J30: 46338 | K30: En cours | L30: 0.7 | M30: =IF($F$2="Données correctes",G30,H30)*L30
A31: 4.3 | B31: Comparer les provisions passées avec les paiements réels (boni et mali de liquidation) | C31: Actuaire Adenka | D31: Chef comptable | F31: Provisions maladie et obsèques identiques depuis le 01/09/2020 : comparaison avec le recalcul (rapport du 23/10/2026, diapositive 136). Boni et mali par exercice en attente des bases avec dates de survenance et de paiement. Items PBC attendus : 16, 47. | G31: 0.5 | H31: 1 | I31: 46331 | J31: 46339 | K31: En cours | L31: 0.4 | M31: =IF($F$2="Données correctes",G31,H31)*L31
A32: 4.4 | B32: Revoir les autres provisions : dépréciation des prêts du Grenier, compte GNA (flotte automobile), départ à la retraite du personnel | C32: Actuaire Adenka | D32: Chef comptable | F32: Rapport du 23/10/2026, diapositives 120 à 133 (Grenier, compte GNA, provision du personnel avec et sans plafond conventionnel) ; classeur FPPN_Calculs_rapport_20261023.xlsx, onglets 12_grenier_tranches, 12_gna_47111106, 14b_pidr_individuel et 27_pidr_plafond. Reste : note de calcul de la provision du personnel. Items PBC attendus : 51, 72, 78. | G32: 0.5 | H32: 0.75 | I32: 46315 | J32: 46332 | K32: En cours | L32: 0.9 | M32: =IF($F$2="Données correctes",G32,H32)*L32
A33: 4.5 | B33: Conclure sur la suffisance des provisions | C33: Actuaire Adenka | F33: Conclusion établie sur les documents reçus (rapport du 23/10/2026, diapositives 135 à 137). | G33: 0.5 | H33: 0.75 | I33: 46316 | J33: 46339 | K33: En cours | L33: 0.7 | M33: =IF($F$2="Données correctes",G33,H33)*L33
A34: 5 | B34: Phase 5 : Adossement et adéquation des placements | F34: Estimation : Mettre actifs et engagements par échéance, mesurer la couverture et la liquidité. | G34: =SUM(G35:G39) | H34: =SUM(H35:H39) | I34: =MIN(I35:I39) | J34: =MAX(J35:J39) | K34: =IF(L34>=1,"Effectuée",IF(AND(L34=0,COUNTIF(K35:K39,"Bloquée")>0),"Bloquée",IF(L34=0,"Non réalisée","En cours"))) | L34: =IFERROR(M34/IF($F$2="Données correctes",G34,H34),0) | M34: =SUM(M35:M39)
A35: 5.1 | B35: Décrire la structure de l'actif, les placements, leurs règles de valorisation et le circuit de décision des placements | C35: Actuaire Adenka | D35: Chef comptable ; direction générale | E35: - Adossement actif-passif (rapport, partie 9) - Échéancier des actifs et des engagements - Conclusion sur l'adéquation des placements | F35: Rapport du 23/10/2026, diapositives 139, 142 et 153 à 155 ; compte rendu de l'entretien placements du 19/10/2026. | G35: 0.5 | H35: 0.5 | I35: 46314 | J35: 46316 | K35: Effectuée | L35: 1 | M35: =IF($F$2="Données correctes",G35,H35)*L35
A36: 5.2 | B36: Mesurer un adossement de liquidité provisoire (borne favorable) et des scénarios de couverture des engagements | C36: Actuaire Adenka | F36: Rapport du 23/10/2026, diapositives 140 à 148 ; classeur FPPN_Calculs_rapport_20261023.xlsx, onglets 10_actif_mobilisation et 8_sensibilite_retraits. | G36: 0.75 | H36: 0.75 | I36: 46315 | J36: 46316 | K36: Effectuée | L36: 1 | M36: =IF($F$2="Données correctes",G36,H36)*L36
A37: 5.3 | B37: Établir l'échéancier des actifs et des engagements et mesurer la couverture et la liquidité par échéance | C37: Actuaire Adenka | D37: Chef comptable | F37: Écoulement de l'épargne et écarts de liquidité année par année (rapport du 23/10/2026, diapositives 145 et 146). Encours des placements lus dans les grands livres (diapositive 153). Reste : inventaire et échéancier signés des placements. Items PBC attendus : 53, 54, 55. | G37: 1 | H37: 1.5 | I37: 46329 | J37: 46339 | K37: En cours | L37: 0.5 | M37: =IF($F$2="Données correctes",G37,H37)*L37
A38: 5.4 | B38: Mesurer le rendement des placements et le comparer aux taux du marché (rendements de l'État de Côte d'Ivoire) | C38: Actuaire Adenka | F38: Encours moyen et rendement lus dans les grands livres (rapport du 23/10/2026, diapositives 153, 156 et 203) ; classeur FPPN_Calculs_rapport_20261023.xlsx, onglets 7_rendement_placements, 26_placements_gl et D9_placements_gl. | G38: 0.25 | H38: 0.5 | I38: 46314 | J38: 46316 | K38: Effectuée | L38: 1 | M38: =IF($F$2="Données correctes",G38,H38)*L38
A39: 5.5 | B39: Conclure sur l'adossement actif-passif et l'adéquation des placements aux engagements | C39: Actuaire Adenka | F39: Conclusions établies sur les documents reçus (rapport du 23/10/2026, diapositives 149 et 157). | G39: 0.5 | H39: 0.75 | I39: 46316 | J39: 46339 | K39: En cours | L39: 0.7 | M39: =IF($F$2="Données correctes",G39,H39)*L39
A40: 6 | B40: Phase 6 : Comparaison avec les indicateurs AIRMS | F40: Estimation : Calculer les ratios du régulateur à chaque date. | G40: =SUM(G41:G44) | H40: =SUM(H41:H44) | I40: =MIN(I41:I44) | J40: =MAX(J41:J44) | K40: =IF(L40>=1,"Effectuée",IF(AND(L40=0,COUNTIF(K41:K44,"Bloquée")>0),"Bloquée",IF(L40=0,"Non réalisée","En cours"))) | L40: =IFERROR(M40/IF($F$2="Données correctes",G40,H40),0) | M40: =SUM(M41:M44)
A41: 6.1 | B41: Calculer les ratios prudentiels de la Décision n° 05/2022/COM/UEMOA à chaque date, en deux lectures (comme le FPPN, puis retraitée) | C41: Actuaire Adenka | E41: - Tableau de bord prudentiel, 2020 au 31/08/2026 - Analyses de sensibilité et leviers de conformité | F41: Rapport du 23/10/2026, diapositives 159 à 179 ; classeur FPPN_Calculs_rapport_20261023.xlsx, onglets 10_ratios et 10_ratios_detail. | G41: 0.4 | H41: 0.75 | I41: 46311 | J41: 46316 | K41: Effectuée | L41: 1 | M41: =IF($F$2="Données correctes",G41,H41)*L41
A42: 6.2 | B42: Contrôler le classement des comptes (PCMS), la marge de solvabilité, l'affectation des excédents et l'excédent par risque | C42: Actuaire Adenka | D42: Chef comptable | F42: Rapport du 23/10/2026, diapositives 180 à 188 (excédent par risque, ratios par garantie, affectation des excédents, marge de solvabilité, dispositif actuariel, plan comptable) ; classeur FPPN_Calculs_rapport_20261023.xlsx, onglets 10_controle_pcms, 10_marge_solvabilite, 10_affectation_excedents et 10_excedent_par_risque. | G42: 0.25 | H42: 0.5 | I42: 46311 | J42: 46316 | K42: Effectuée | L42: 1 | M42: =IF($F$2="Données correctes",G42,H42)*L42
A43: 6.3 | B43: Mener les analyses de sensibilité et chiffrer les leviers de conformité (montant à combler, effet de chaque levier) | C43: Actuaire Adenka | F43: Rapport du 23/10/2026, diapositives 191 à 204 ; classeur FPPN_Calculs_rapport_20261023.xlsx, onglets 13a à 13i. | G43: 0.25 | H43: 0.5 | I43: 46315 | J43: 46316 | K43: Effectuée | L43: 1 | M43: =IF($F$2="Données correctes",G43,H43)*L43
...

Sheet Synthèse-PT_Actuariat
A1: Tableau 1 : Avancement par phase au 23/10/2026
A2: Calculé à partir de l'onglet « Plan de travail » : toute mise à jour des statuts et des taux s'y reporte. Le temps restant est le temps estimé du scénario choisi moins le temps réalisé équivalent.
A4: Phase | B4: Temps estimé, données correctes (j) | C4: Temps estimé, données dégradées (j) | D4: Temps réalisé équivalent (j) | E4: Temps restant (j) | F4: Taux de réalisation | G4: Effectuées | H4: En cours | I4: Bloquées | J4: Non réalisées | K4: Sous-activités
A5: =PT_Actuariat!B7 | B5: =PT_Actuariat!G7 | C5: =PT_Actuariat!H7 | D5: =PT_Actuariat!M7 | E5: =IF(PT_Actuariat!$F$2="Données correctes",B5,C5)-D5 | F5: =PT_Actuariat!L7 | G5: =COUNTIF(PT_Actuariat!K8:K12,"Effectuée") | H5: =COUNTIF(PT_Actuariat!K8:K12,"En cours") | I5: =COUNTIF(PT_Actuariat!K8:K12,"Bloquée") | J5: =COUNTIF(PT_Actuariat!K8:K12,"Non réalisée") | K5: =COUNTA(PT_Actuariat!K8:K12)
A6: =PT_Actuariat!B13 | B6: =PT_Actuariat!G13 | C6: =PT_Actuariat!H13 | D6: =PT_Actuariat!M13 | E6: =IF(PT_Actuariat!$F$2="Données correctes",B6,C6)-D6 | F6: =PT_Actuariat!L13 | G6: =COUNTIF(PT_Actuariat!K14:K20,"Effectuée") | H6: =COUNTIF(PT_Actuariat!K14:K20,"En cours") | I6: =COUNTIF(PT_Actuariat!K14:K20,"Bloquée") | J6: =COUNTIF(PT_Actuariat!K14:K20,"Non réalisée") | K6: =COUNTA(PT_Actuariat!K14:K20)
A7: =PT_Actuariat!B21 | B7: =PT_Actuariat!G21 | C7: =PT_Actuariat!H21 | D7: =PT_Actuariat!M21 | E7: =IF(PT_Actuariat!$F$2="Données correctes",B7,C7)-D7 | F7: =PT_Actuariat!L21 | G7: =COUNTIF(PT_Actuariat!K22:K27,"Effectuée") | H7: =COUNTIF(PT_Actuariat!K22:K27,"En cours") | I7: =COUNTIF(PT_Actuariat!K22:K27,"Bloquée") | J7: =COUNTIF(PT_Actuariat!K22:K27,"Non réalisée") | K7: =COUNTA(PT_Actuariat!K22:K27)
A8: =PT_Actuariat!B28 | B8: =PT_Actuariat!G28 | C8: =PT_Actuariat!H28 | D8: =PT_Actuariat!M28 | E8: =IF(PT_Actuariat!$F$2="Données correctes",B8,C8)-D8 | F8: =PT_Actuariat!L28 | G8: =COUNTIF(PT_Actuariat!K29:K33,"Effectuée") | H8: =COUNTIF(PT_Actuariat!K29:K33,"En cours") | I8: =COUNTIF(PT_Actuariat!K29:K33,"Bloquée") | J8: =COUNTIF(PT_Actuariat!K29:K33,"Non réalisée") | K8: =COUNTA(PT_Actuariat!K29:K33)
A9: =PT_Actuariat!B34 | B9: =PT_Actuariat!G34 | C9: =PT_Actuariat!H34 | D9: =PT_Actuariat!M34 | E9: =IF(PT_Actuariat!$F$2="Données correctes",B9,C9)-D9 | F9: =PT_Actuariat!L34 | G9: =COUNTIF(PT_Actuariat!K35:K39,"Effectuée") | H9: =COUNTIF(PT_Actuariat!K35:K39,"En cours") | I9: =COUNTIF(PT_Actuariat!K35:K39,"Bloquée") | J9: =COUNTIF(PT_Actuariat!K35:K39,"Non réalisée") | K9: =COUNTA(PT_Actuariat!K35:K39)
A10: =PT_Actuariat!B40 | B10: =PT_Actuariat!G40 | C10: =PT_Actuariat!H40 | D10: =PT_Actuariat!M40 | E10: =IF(PT_Actuariat!$F$2="Données correctes",B10,C10)-D10 | F10: =PT_Actuariat!L40 | G10: =COUNTIF(PT_Actuariat!K41:K44,"Effectuée") | H10: =COUNTIF(PT_Actuariat!K41:K44,"En cours") | I10: =COUNTIF(PT_Actuariat!K41:K44,"Bloquée") | J10: =COUNTIF(PT_Actuariat!K41:K44,"Non réalisée") | K10: =COUNTA(PT_Actuariat!K41:K44)
A11: =PT_Actuariat!B45 | B11: =PT_Actuariat!G45 | C11: =PT_Actuariat!H45 | D11: =PT_Actuariat!M45 | E11: =IF(PT_Actuariat!$F$2="Données correctes",B11,C11)-D11 | F11: =PT_Actuariat!L45 | G11: =COUNTIF(PT_Actuariat!K46:K48,"Effectuée") | H11: =COUNTIF(PT_Actuariat!K46:K48,"En cours") | I11: =COUNTIF(PT_Actuariat!K46:K48,"Bloquée") | J11: =COUNTIF(PT_Actuariat!K46:K48,"Non réalisée") | K11: =COUNTA(PT_Actuariat!K46:K48)
A12: =PT_Actuariat!B49 | B12: =PT_Actuariat!G49 | C12: =PT_Actuariat!H49 | D12: =PT_Actuariat!M49 | E12: =IF(PT_Actuariat!$F$2="Données correctes",B12,C12)-D12 | F12: =PT_Actuariat!L49 | G12: =COUNTIF(PT_Actuariat!K50:K55,"Effectuée") | H12: =COUNTIF(PT_Actuariat!K50:K55,"En cours") | I12: =COUNTIF(PT_Actuariat!K50:K55,"Bloquée") | J12: =COUNTIF(PT_Actuariat!K50:K55,"Non réalisée") | K12: =COUNTA(PT_Actuariat!K50:K55)
A13: Total de la mission | B13: =SUM(B5:B12) | C13: =SUM(C5:C12) | D13: =SUM(D5:D12) | E13: =SUM(E5:E12) | F13: =PT_Actuariat!L56 | G13: =SUM(G5:G12) | H13: =SUM(H5:H12) | I13: =SUM(I5:I12) | J13: =SUM(J5:J12) | K13: =SUM(K5:K12)
A14: Source : onglet « Plan de travail » ; pointage Adenka au 23/10/2026
A16: Figure 1 : Taux de réalisation par phase au 23/10/2026
A36: Source : onglet « Plan de travail » ; pointage Adenka

Sheet Documents attendus
A1: Tableau 2 : Documents de la PBC dont dépendent les sous-activités bloquées ou en cours
A2: Numéros et statuts repris de la PBC pointée au 23/10/2026 (FPPN_PBC_complete_pointee_20261023.xlsx). Doublons fusionnés : un numéro par document.
A4: 1 | B4: Statuts et règlement intérieur en vigueur, ainsi que les versions applicables entre le 1er janvier 2020 et le 31 août 2026, avec leurs dates d'adoption. | C4: Partiellement Reçu | D4: 1.3 | E4: Limite la conclusion
A5: 3 | B5: Tout rapport actuariel, étude technique ou note de calcul des engagements envers les mutualistes existant, quelle que soit sa date. | C5: Partiellement Reçu | D5: 6.4 | E5: Bloque la sous-activité
A6: 4 | B6: Fichier des mutualistes à chacune des dates suivantes : 31/12/2019, 31/12/2020, 31/12/2021, 31/12/2022, 31/12/2023, 31/12/2024, 31/12/2025 et 31/08/2026. Une ligne par mutualiste : matricule, date de naissance, sexe, date d'entrée dans la police, date d'adhésion au FPPN, statut (actif, retraité, sorti, décédé), date et motif de sortie, montant de la cotisation mensuelle. | C6: Partiellement Reçu | D6: 3.1, 3.5 | E6: Bloque la sous-activité
A7: 7 | B7: Liste des dossiers de prestations non payés à chacune des dates suivantes : 31/12/2019, 31/12/2020, 31/12/2021, 31/12/2022, 31/12/2023, 31/12/2024, 31/12/2025 et 31/08/2026, y compris les factures des prestataires de santé non réglées. Une ligne par dossier : matricule, type de prestation, date de l'événement, date de déclaration, montant dû. | C7: Partiellement Reçu | D7: 4.2 | E7: Bloque la sous-activité
A8: 9 | B8: Comptes individuels d'épargne de 2020 au 31/08/2026. Une ligne par mutualiste et par année : solde d'ouverture, versements, intérêts crédités, retraits, solde de clôture. | C8: Partiellement Reçu | D8: 2.5 | E8: Limite la conclusion
A9: 13 | B9: Âge de départ à la retraite des fonctionnaires de police, par grade le cas échéant, et texte de référence. | C9: Non Reçu | D9: 1.5 | E9: Limite la conclusion
A10: 16 | B10: Base des sinistres décès et allocations du 01/01/2019 au 31/08/2026, une ligne par dossier, au format de l'onglet « Modèle données décès » : matricule, grade, date de naissance, bénéficiaire (policier, conjoint, enfant), date du décès, date de déclaration, date de dossier complet, date de paiement, capital, frais funéraires, statut. | C10: Partiellement Reçu | D10: 2.6, 3.5, 4.3 | E10: Bloque la sous-activité
A11: 28 | B11: Rapports du commissaire aux comptes 2020 à 2025 et états financiers par risque long (règlement d'exécution n° 004/2022, art. 12 et 13). | C11: Partiellement Reçu | D11: 6.4 | E11: Bloque la sous-activité
A12: 29 | B12: Attestation d'adhésion au FOMUS-CI, appels de cotisation et preuves de paiement 2022 à 2026. | C12: Non Reçu | D12: 6.4 | E12: Bloque la sous-activité
A13: 30 | B13: Registre des contrôles a posteriori des factures et montants de prestations indues récupérés, 2022 à 2026. | C13: Non Reçu | D13: 6.4 | E13: Bloque la sous-activité
A14: 38 | B14: Fichiers aller maladie (poste 936) et décès (poste 8Z6), de janvier 2020 à août 2026, transmis par la direction du personnel de la Police à la Solde (aucun fichier aller reçu sur 80 mois, voir l'onglet « Fichiers manquants » de la PBC complémentaire cotisations). | C14: Non Reçu | D14: 2.4 | E14: Bloque la sous-activité
A15: 39 | B15: Fichiers retour maladie (936) et décès (8Z6) manquants ou vides : « 122024_effectif_police_936_DECEMBRE 2024.xlsx » et « FPPN_ALLOC_DECES_8Z6_DECEMBRE_2024.xlsx » (reçus vides, 0 octet) ; retours 8Z6 de mai à octobre 2024 et d'avril 2025 ; retours 936 et 8Z6 de janvier 2020 à décembre 2023. | C15: Non Reçu | D15: 2.4 | E15: Bloque la sous-activité
... A26: 78 | B26: Personnel : âge de départ à la retraite appliqué, nombre d'enfants à charge de chaque salarié, justification des douze dates d'embauche modifiées dans la DISA 2025, rattachement (Direction Générale, CMP, Grenier) des dix-neuf agents recrutés en 2025, note et fichiers de calcul de la provision pour départ à la retraite (compte 196) de 2020 à 2026 : méthode, hypothèses, liste des salariés. | C26: Non Reçu | D26: 4.4 | E26: Limite la conclusion
A27: Source : PBC pointée au 23/10/2026 ; onglet « Plan de travail »

Sheet Mode d'emploi
A1: Mode d'emploi du plan de travail
A3: Structure
A4: Phases | B4: Les huit phases sont les activités de l'estimation du temps de la mission (26 j si les données sont correctes, 39 j si elles sont dégradées).
A5: Sous-activités | B5: Chaque phase est détaillée en sous-activités. Leur temps estimé redonne exactement le temps de la phase dans les deux scénarios.
A6: Pointage | B6: La colonne « Observations et pièces justificatives » cite la pièce qui justifie le statut (rapport et classeur des calculs du 23/10/2026, PBC, comptes rendus) et les items de la PBC attendus.
A8: Mise à jour
A9: Statut | B9: Liste déroulante sur chaque sous-activité. Le statut des phases et de la mission est calculé.
A10: Taux de réalisation | B10: Saisie libre entre 0 % et 100 % sur chaque sous-activité.
A11: Scénario | B11: Cellule orange F2 de l'onglet « Plan de travail » : données dégradées (par défaut) ou données correctes.
A12: Dates | B12: Les colonnes « Début prévu » et « Fin prévue » pilotent le diagramme ; le modifier revient à changer ces dates.
A14: Calculs
A15: Temps réalisé équivalent | B15: Temps estimé du scénario choisi multiplié par le taux de réalisation de la sous-activité.
A16: Taux d'une phase | B16: Somme des temps réalisés équivalents de la phase divisée par son temps estimé : moyenne des taux pondérée par le temps.
A17: Taux de la mission | B17: Somme des temps réalisés équivalents divisée par le temps estimé total du scénario choisi.
A18: Statut d'une phase | B18: Effectuée à 100 % ; Bloquée si le taux est nul et qu'une sous-activité est bloquée ; Non réalisée si le taux est nul ; En cours sinon.
A20: Statuts
A21: Effectuée | B21: Travail terminé, pièce justificative disponible.
A22: En cours | B22: Travail engagé, résultat provisoire ou partiel.
A23: Bloquée | B23: Travail arrêté ou limité dans l'attente de documents du FPPN (items de la PBC cités).
A24: Non réalisée | B24: Travail non commencé, selon le calendrier prévu.
